Caught a TypeError('A type error')
  File 'test/testExceptionTracebacks.krk', line 14, in __main__
  File 'test/testExceptionTracebacks.krk', line 4, in doTheThing
Caught a ValueError('A value error')
  File 'test/testExceptionTracebacks.krk', line 15, in __main__
  File 'test/testExceptionTracebacks.krk', line 4, in doTheThing
That's a name error!
